[2024-05-17T21:06:49.395+0000] {local_task_job_runner.py:120} INFO - ::group::Pre task execution logs
[2024-05-17T21:06:49.440+0000] {taskinstance.py:2076} INFO - Dependencies all met for dep_context=non-requeueable deps ti=<TaskInstance: data_ingestion_pipelines_2.save_file manual__2024-05-17T12:31:17.083416+00:00 [queued]>
[2024-05-17T21:06:49.454+0000] {taskinstance.py:2076} INFO - Dependencies all met for dep_context=requeueable deps ti=<TaskInstance: data_ingestion_pipelines_2.save_file manual__2024-05-17T12:31:17.083416+00:00 [queued]>
[2024-05-17T21:06:49.457+0000] {taskinstance.py:2306} INFO - Starting attempt 11 of 11
[2024-05-17T21:06:49.475+0000] {taskinstance.py:2330} INFO - Executing <Task(PythonOperator): save_file> on 2024-05-17 12:31:17.083416+00:00
[2024-05-17T21:06:49.485+0000] {warnings.py:110} WARNING - /home/***/.local/lib/python3.12/site-packages/***/task/task_runner/standard_task_runner.py:61: DeprecationWarning: This process (pid=12218) is multi-threaded, use of fork() may lead to deadlocks in the child.
  pid = os.fork()

[2024-05-17T21:06:49.487+0000] {standard_task_runner.py:63} INFO - Started process 12228 to run task
[2024-05-17T21:06:49.487+0000] {standard_task_runner.py:90} INFO - Running: ['***', 'tasks', 'run', 'data_ingestion_pipelines_2', 'save_file', 'manual__2024-05-17T12:31:17.083416+00:00', '--job-id', '106', '--raw', '--subdir', 'DAGS_FOLDER/data-ingestion-dag.py', '--cfg-path', '/tmp/tmpf17f8bwu']
[2024-05-17T21:06:49.488+0000] {standard_task_runner.py:91} INFO - Job 106: Subtask save_file
[2024-05-17T21:06:49.551+0000] {task_command.py:426} INFO - Running <TaskInstance: data_ingestion_pipelines_2.save_file manual__2024-05-17T12:31:17.083416+00:00 [running]> on host e512d0910ba5
[2024-05-17T21:06:49.654+0000] {taskinstance.py:2648} INFO - Exporting env vars: AIRFLOW_CTX_DAG_OWNER='***' AIRFLOW_CTX_DAG_ID='data_ingestion_pipelines_2' AIRFLOW_CTX_TASK_ID='save_file' AIRFLOW_CTX_EXECUTION_DATE='2024-05-17T12:31:17.083416+00:00' AIRFLOW_CTX_TRY_NUMBER='11' AIRFLOW_CTX_DAG_RUN_ID='manual__2024-05-17T12:31:17.083416+00:00'
[2024-05-17T21:06:49.655+0000] {taskinstance.py:430} INFO - ::endgroup::
[2024-05-17T21:06:49.714+0000] {taskinstance.py:441} INFO - ::group::Post task execution logs
[2024-05-17T21:06:49.715+0000] {taskinstance.py:2905} ERROR - Task failed with exception
Traceback (most recent call last):
  File "/home/airflow/.local/lib/python3.12/site-packages/airflow/models/taskinstance.py", line 465, in _execute_task
    result = _execute_callable(context=context, **execute_callable_kwargs)
             ^^^^^^^^^^^^^^^^^^^^^^^^^^^^^^^^^^^^^^^^^^^^^^^^^^^^^^^^^^^^^
  File "/home/airflow/.local/lib/python3.12/site-packages/airflow/models/taskinstance.py", line 432, in _execute_callable
    return execute_callable(context=context, **execute_callable_kwargs)
           ^^^^^^^^^^^^^^^^^^^^^^^^^^^^^^^^^^^^^^^^^^^^^^^^^^^^^^^^^^^^
  File "/home/airflow/.local/lib/python3.12/site-packages/airflow/models/baseoperator.py", line 400, in wrapper
    return func(self, *args, **kwargs)
           ^^^^^^^^^^^^^^^^^^^^^^^^^^^
  File "/home/airflow/.local/lib/python3.12/site-packages/airflow/operators/python.py", line 235, in execute
    return_value = self.execute_callable()
                   ^^^^^^^^^^^^^^^^^^^^^^^
  File "/home/airflow/.local/lib/python3.12/site-packages/airflow/operators/python.py", line 252, in execute_callable
    return self.python_callable(*self.op_args, **self.op_kwargs)
           ^^^^^^^^^^^^^^^^^^^^^^^^^^^^^^^^^^^^^^^^^^^^^^^^^^^^^
  File "/opt/airflow/dags/data-ingestion-dag.py", line 175, in save_file
    for result in validation_results["results"]:
                  ~~~~~~~~~~~~~~~~~~^^^^^^^^^^^
TypeError: string indices must be integers, not 'str'
[2024-05-17T21:06:49.728+0000] {taskinstance.py:1206} INFO - Marking task as FAILED. dag_id=data_ingestion_pipelines_2, task_id=save_file, run_id=manual__2024-05-17T12:31:17.083416+00:00, execution_date=20240517T123117, start_date=20240517T210649, end_date=20240517T210649
[2024-05-17T21:06:49.748+0000] {standard_task_runner.py:110} ERROR - Failed to execute job 106 for task save_file (string indices must be integers, not 'str'; 12228)
[2024-05-17T21:06:49.783+0000] {local_task_job_runner.py:240} INFO - Task exited with return code 1
[2024-05-17T21:06:49.812+0000] {taskinstance.py:3498} INFO - 0 downstream tasks scheduled from follow-on schedule check
[2024-05-17T21:06:49.816+0000] {local_task_job_runner.py:222} INFO - ::endgroup::
