[2024-05-17T20:57:51.602+0000] {local_task_job_runner.py:120} INFO - ::group::Pre task execution logs
[2024-05-17T20:57:51.664+0000] {taskinstance.py:2076} INFO - Dependencies all met for dep_context=non-requeueable deps ti=<TaskInstance: data_ingestion_pipelines_2.validate_data manual__2024-05-17T12:31:17.083416+00:00 [queued]>
[2024-05-17T20:57:51.679+0000] {taskinstance.py:2076} INFO - Dependencies all met for dep_context=requeueable deps ti=<TaskInstance: data_ingestion_pipelines_2.validate_data manual__2024-05-17T12:31:17.083416+00:00 [queued]>
[2024-05-17T20:57:51.682+0000] {taskinstance.py:2306} INFO - Starting attempt 38 of 38
[2024-05-17T20:57:51.704+0000] {taskinstance.py:2330} INFO - Executing <Task(PythonOperator): validate_data> on 2024-05-17 12:31:17.083416+00:00
[2024-05-17T20:57:51.719+0000] {warnings.py:110} WARNING - /home/***/.local/lib/python3.12/site-packages/***/task/task_runner/standard_task_runner.py:61: DeprecationWarning: This process (pid=11563) is multi-threaded, use of fork() may lead to deadlocks in the child.
  pid = os.fork()

[2024-05-17T20:57:51.722+0000] {standard_task_runner.py:63} INFO - Started process 11585 to run task
[2024-05-17T20:57:51.724+0000] {standard_task_runner.py:90} INFO - Running: ['***', 'tasks', 'run', 'data_ingestion_pipelines_2', 'validate_data', 'manual__2024-05-17T12:31:17.083416+00:00', '--job-id', '96', '--raw', '--subdir', 'DAGS_FOLDER/data-ingestion-dag.py', '--cfg-path', '/tmp/tmpi4rtug6a']
[2024-05-17T20:57:51.728+0000] {standard_task_runner.py:91} INFO - Job 96: Subtask validate_data
[2024-05-17T20:57:51.809+0000] {task_command.py:426} INFO - Running <TaskInstance: data_ingestion_pipelines_2.validate_data manual__2024-05-17T12:31:17.083416+00:00 [running]> on host e512d0910ba5
[2024-05-17T20:57:51.953+0000] {taskinstance.py:2648} INFO - Exporting env vars: AIRFLOW_CTX_DAG_OWNER='***' AIRFLOW_CTX_DAG_ID='data_ingestion_pipelines_2' AIRFLOW_CTX_TASK_ID='validate_data' AIRFLOW_CTX_EXECUTION_DATE='2024-05-17T12:31:17.083416+00:00' AIRFLOW_CTX_TRY_NUMBER='38' AIRFLOW_CTX_DAG_RUN_ID='manual__2024-05-17T12:31:17.083416+00:00'
[2024-05-17T20:57:51.955+0000] {taskinstance.py:430} INFO - ::endgroup::
[2024-05-17T20:57:51.989+0000] {logging_mixin.py:188} INFO - file_path in validate_data is  /opt/***/dags/raw-data/data_part_1.csv
[2024-05-17T20:57:51.990+0000] {logging_mixin.py:188} INFO - data_asset_name is  data_part_1
[2024-05-17T20:57:51.991+0000] {taskinstance.py:441} INFO - ::group::Post task execution logs
[2024-05-17T20:57:51.992+0000] {taskinstance.py:2905} ERROR - Task failed with exception
Traceback (most recent call last):
  File "/home/airflow/.local/lib/python3.12/site-packages/airflow/models/taskinstance.py", line 465, in _execute_task
    result = _execute_callable(context=context, **execute_callable_kwargs)
             ^^^^^^^^^^^^^^^^^^^^^^^^^^^^^^^^^^^^^^^^^^^^^^^^^^^^^^^^^^^^^
  File "/home/airflow/.local/lib/python3.12/site-packages/airflow/models/taskinstance.py", line 432, in _execute_callable
    return execute_callable(context=context, **execute_callable_kwargs)
           ^^^^^^^^^^^^^^^^^^^^^^^^^^^^^^^^^^^^^^^^^^^^^^^^^^^^^^^^^^^^
  File "/home/airflow/.local/lib/python3.12/site-packages/airflow/models/baseoperator.py", line 400, in wrapper
    return func(self, *args, **kwargs)
           ^^^^^^^^^^^^^^^^^^^^^^^^^^^
  File "/home/airflow/.local/lib/python3.12/site-packages/airflow/operators/python.py", line 235, in execute
    return_value = self.execute_callable()
                   ^^^^^^^^^^^^^^^^^^^^^^^
  File "/home/airflow/.local/lib/python3.12/site-packages/airflow/operators/python.py", line 252, in execute_callable
    return self.python_callable(*self.op_args, **self.op_kwargs)
           ^^^^^^^^^^^^^^^^^^^^^^^^^^^^^^^^^^^^^^^^^^^^^^^^^^^^^
  File "/opt/airflow/dags/data-ingestion-dag.py", line 57, in validate_data
    df = read_and_prepare_data(file_path)
         ^^^^^^^^^^^^^^^^^^^^^
NameError: name 'read_and_prepare_data' is not defined
[2024-05-17T20:57:52.020+0000] {taskinstance.py:1206} INFO - Marking task as FAILED. dag_id=data_ingestion_pipelines_2, task_id=validate_data, run_id=manual__2024-05-17T12:31:17.083416+00:00, execution_date=20240517T123117, start_date=20240517T205751, end_date=20240517T205752
[2024-05-17T20:57:52.041+0000] {standard_task_runner.py:110} ERROR - Failed to execute job 96 for task validate_data (name 'read_and_prepare_data' is not defined; 11585)
[2024-05-17T20:57:52.059+0000] {local_task_job_runner.py:240} INFO - Task exited with return code 1
[2024-05-17T20:57:52.092+0000] {taskinstance.py:3498} INFO - 0 downstream tasks scheduled from follow-on schedule check
[2024-05-17T20:57:52.099+0000] {local_task_job_runner.py:222} INFO - ::endgroup::
