[2024-05-17T19:50:02.648+0000] {local_task_job_runner.py:120} INFO - ::group::Pre task execution logs
[2024-05-17T19:50:02.811+0000] {taskinstance.py:2076} INFO - Dependencies all met for dep_context=non-requeueable deps ti=<TaskInstance: data_ingestion_pipelines_2.validate_data manual__2024-05-17T12:31:17.083416+00:00 [queued]>
[2024-05-17T19:50:02.855+0000] {taskinstance.py:2076} INFO - Dependencies all met for dep_context=requeueable deps ti=<TaskInstance: data_ingestion_pipelines_2.validate_data manual__2024-05-17T12:31:17.083416+00:00 [queued]>
[2024-05-17T19:50:02.857+0000] {taskinstance.py:2306} INFO - Starting attempt 21 of 21
[2024-05-17T19:50:02.934+0000] {taskinstance.py:2330} INFO - Executing <Task(PythonOperator): validate_data> on 2024-05-17 12:31:17.083416+00:00
[2024-05-17T19:50:02.976+0000] {standard_task_runner.py:90} INFO - Running: ['***', 'tasks', 'run', 'data_ingestion_pipelines_2', 'validate_data', 'manual__2024-05-17T12:31:17.083416+00:00', '--job-id', '36', '--raw', '--subdir', 'DAGS_FOLDER/data-ingestion-dag.py', '--cfg-path', '/tmp/tmpz_znwpot']
[2024-05-17T19:50:02.974+0000] {warnings.py:110} WARNING - /home/***/.local/lib/python3.12/site-packages/***/task/task_runner/standard_task_runner.py:61: DeprecationWarning: This process (pid=6803) is multi-threaded, use of fork() may lead to deadlocks in the child.
  pid = os.fork()

[2024-05-17T19:50:02.982+0000] {standard_task_runner.py:63} INFO - Started process 6830 to run task
[2024-05-17T19:50:02.982+0000] {standard_task_runner.py:91} INFO - Job 36: Subtask validate_data
[2024-05-17T19:50:03.181+0000] {task_command.py:426} INFO - Running <TaskInstance: data_ingestion_pipelines_2.validate_data manual__2024-05-17T12:31:17.083416+00:00 [running]> on host e512d0910ba5
[2024-05-17T19:50:03.461+0000] {taskinstance.py:2648} INFO - Exporting env vars: AIRFLOW_CTX_DAG_OWNER='***' AIRFLOW_CTX_DAG_ID='data_ingestion_pipelines_2' AIRFLOW_CTX_TASK_ID='validate_data' AIRFLOW_CTX_EXECUTION_DATE='2024-05-17T12:31:17.083416+00:00' AIRFLOW_CTX_TRY_NUMBER='21' AIRFLOW_CTX_DAG_RUN_ID='manual__2024-05-17T12:31:17.083416+00:00'
[2024-05-17T19:50:03.464+0000] {taskinstance.py:430} INFO - ::endgroup::
[2024-05-17T19:50:03.527+0000] {logging_mixin.py:188} INFO - file_path in validate_data is  /opt/***/dags/raw-data/data_part_9.csv
[2024-05-17T19:50:03.528+0000] {logging_mixin.py:188} INFO - data_asset_name is  data_part_9
[2024-05-17T19:50:03.648+0000] {warnings.py:110} WARNING - /home/***/.local/lib/python3.12/site-packages/great_expectations/data_context/data_context/base_data_context.py:158: DeprecationWarning: DataContext and BaseDataContext are deprecated as of v0.17.10 and will be removed in v0.20. Please use gx.get_context instead.
  warnings.warn(

[2024-05-17T19:50:03.756+0000] {file_data_context.py:222} INFO - FileDataContext loading fluent config
[2024-05-17T19:50:03.826+0000] {config.py:187} INFO - Loading 'datasources' ->
[]
[2024-05-17T19:50:04.536+0000] {taskinstance.py:441} INFO - ::group::Post task execution logs
[2024-05-17T19:50:04.539+0000] {taskinstance.py:2905} ERROR - Task failed with exception
Traceback (most recent call last):
  File "/home/airflow/.local/lib/python3.12/site-packages/airflow/models/taskinstance.py", line 465, in _execute_task
    result = _execute_callable(context=context, **execute_callable_kwargs)
             ^^^^^^^^^^^^^^^^^^^^^^^^^^^^^^^^^^^^^^^^^^^^^^^^^^^^^^^^^^^^^
  File "/home/airflow/.local/lib/python3.12/site-packages/airflow/models/taskinstance.py", line 432, in _execute_callable
    return execute_callable(context=context, **execute_callable_kwargs)
           ^^^^^^^^^^^^^^^^^^^^^^^^^^^^^^^^^^^^^^^^^^^^^^^^^^^^^^^^^^^^
  File "/home/airflow/.local/lib/python3.12/site-packages/airflow/models/baseoperator.py", line 400, in wrapper
    return func(self, *args, **kwargs)
           ^^^^^^^^^^^^^^^^^^^^^^^^^^^
  File "/home/airflow/.local/lib/python3.12/site-packages/airflow/operators/python.py", line 235, in execute
    return_value = self.execute_callable()
                   ^^^^^^^^^^^^^^^^^^^^^^^
  File "/home/airflow/.local/lib/python3.12/site-packages/airflow/operators/python.py", line 252, in execute_callable
    return self.python_callable(*self.op_args, **self.op_kwargs)
           ^^^^^^^^^^^^^^^^^^^^^^^^^^^^^^^^^^^^^^^^^^^^^^^^^^^^^
  File "/opt/airflow/dags/data-ingestion-dag.py", line 62, in validate_data
    expectation_suite = context.get_expectation_suite(expectation_suite_name)
                        ^^^^^^^^^^^^^^^^^^^^^^^^^^^^^^^^^^^^^^^^^^^^^^^^^^^^^
  File "/home/airflow/.local/lib/python3.12/site-packages/great_expectations/data_context/data_context/abstract_data_context.py", line 3033, in get_expectation_suite
    raise gx_exceptions.DataContextError(
great_expectations.exceptions.exceptions.DataContextError: expectation_suite my_ex not found
[2024-05-17T19:50:04.587+0000] {taskinstance.py:1206} INFO - Marking task as FAILED. dag_id=data_ingestion_pipelines_2, task_id=validate_data, run_id=manual__2024-05-17T12:31:17.083416+00:00, execution_date=20240517T123117, start_date=20240517T195002, end_date=20240517T195004
[2024-05-17T19:50:04.632+0000] {standard_task_runner.py:110} ERROR - Failed to execute job 36 for task validate_data (expectation_suite my_ex not found; 6830)
[2024-05-17T19:50:04.697+0000] {local_task_job_runner.py:240} INFO - Task exited with return code 1
[2024-05-17T19:50:04.798+0000] {taskinstance.py:3498} INFO - 0 downstream tasks scheduled from follow-on schedule check
[2024-05-17T19:50:04.811+0000] {local_task_job_runner.py:222} INFO - ::endgroup::
