[2024-05-17T19:19:41.705+0000] {local_task_job_runner.py:120} INFO - ::group::Pre task execution logs
[2024-05-17T19:19:41.741+0000] {taskinstance.py:2076} INFO - Dependencies all met for dep_context=non-requeueable deps ti=<TaskInstance: data_ingestion_pipelines_2.validate_data manual__2024-05-17T12:31:17.083416+00:00 [queued]>
[2024-05-17T19:19:41.750+0000] {taskinstance.py:2076} INFO - Dependencies all met for dep_context=requeueable deps ti=<TaskInstance: data_ingestion_pipelines_2.validate_data manual__2024-05-17T12:31:17.083416+00:00 [queued]>
[2024-05-17T19:19:41.752+0000] {taskinstance.py:2306} INFO - Starting attempt 12 of 12
[2024-05-17T19:19:41.771+0000] {taskinstance.py:2330} INFO - Executing <Task(PythonOperator): validate_data> on 2024-05-17 12:31:17.083416+00:00
[2024-05-17T19:19:41.780+0000] {warnings.py:110} WARNING - /home/***/.local/lib/python3.12/site-packages/***/task/task_runner/standard_task_runner.py:61: DeprecationWarning: This process (pid=4783) is multi-threaded, use of fork() may lead to deadlocks in the child.
  pid = os.fork()

[2024-05-17T19:19:41.782+0000] {standard_task_runner.py:63} INFO - Started process 4793 to run task
[2024-05-17T19:19:41.782+0000] {standard_task_runner.py:90} INFO - Running: ['***', 'tasks', 'run', 'data_ingestion_pipelines_2', 'validate_data', 'manual__2024-05-17T12:31:17.083416+00:00', '--job-id', '18', '--raw', '--subdir', 'DAGS_FOLDER/data-ingestion-dag.py', '--cfg-path', '/tmp/tmp76n4uga4']
[2024-05-17T19:19:41.784+0000] {standard_task_runner.py:91} INFO - Job 18: Subtask validate_data
[2024-05-17T19:19:41.842+0000] {task_command.py:426} INFO - Running <TaskInstance: data_ingestion_pipelines_2.validate_data manual__2024-05-17T12:31:17.083416+00:00 [running]> on host e512d0910ba5
[2024-05-17T19:19:41.945+0000] {taskinstance.py:2648} INFO - Exporting env vars: AIRFLOW_CTX_DAG_OWNER='***' AIRFLOW_CTX_DAG_ID='data_ingestion_pipelines_2' AIRFLOW_CTX_TASK_ID='validate_data' AIRFLOW_CTX_EXECUTION_DATE='2024-05-17T12:31:17.083416+00:00' AIRFLOW_CTX_TRY_NUMBER='12' AIRFLOW_CTX_DAG_RUN_ID='manual__2024-05-17T12:31:17.083416+00:00'
[2024-05-17T19:19:41.947+0000] {taskinstance.py:430} INFO - ::endgroup::
[2024-05-17T19:19:41.977+0000] {logging_mixin.py:188} INFO - file_path in validate_data is  /opt/***/dags/raw-data/data_part_8.csv
[2024-05-17T19:19:41.978+0000] {logging_mixin.py:188} INFO - data_asset_name is  data_part_8
[2024-05-17T19:19:42.040+0000] {warnings.py:110} WARNING - /home/***/.local/lib/python3.12/site-packages/great_expectations/data_context/data_context/base_data_context.py:158: DeprecationWarning: DataContext and BaseDataContext are deprecated as of v0.17.10 and will be removed in v0.20. Please use gx.get_context instead.
  warnings.warn(

[2024-05-17T19:19:42.099+0000] {file_data_context.py:222} INFO - FileDataContext loading fluent config
[2024-05-17T19:19:42.128+0000] {config.py:187} INFO - Loading 'datasources' ->
[]
[2024-05-17T19:19:42.646+0000] {taskinstance.py:441} INFO - ::group::Post task execution logs
[2024-05-17T19:19:42.647+0000] {taskinstance.py:2905} ERROR - Task failed with exception
Traceback (most recent call last):
  File "/home/airflow/.local/lib/python3.12/site-packages/airflow/models/taskinstance.py", line 465, in _execute_task
    result = _execute_callable(context=context, **execute_callable_kwargs)
             ^^^^^^^^^^^^^^^^^^^^^^^^^^^^^^^^^^^^^^^^^^^^^^^^^^^^^^^^^^^^^
  File "/home/airflow/.local/lib/python3.12/site-packages/airflow/models/taskinstance.py", line 432, in _execute_callable
    return execute_callable(context=context, **execute_callable_kwargs)
           ^^^^^^^^^^^^^^^^^^^^^^^^^^^^^^^^^^^^^^^^^^^^^^^^^^^^^^^^^^^^
  File "/home/airflow/.local/lib/python3.12/site-packages/airflow/models/baseoperator.py", line 400, in wrapper
    return func(self, *args, **kwargs)
           ^^^^^^^^^^^^^^^^^^^^^^^^^^^
  File "/home/airflow/.local/lib/python3.12/site-packages/airflow/operators/python.py", line 235, in execute
    return_value = self.execute_callable()
                   ^^^^^^^^^^^^^^^^^^^^^^^
  File "/home/airflow/.local/lib/python3.12/site-packages/airflow/operators/python.py", line 252, in execute_callable
    return self.python_callable(*self.op_args, **self.op_kwargs)
           ^^^^^^^^^^^^^^^^^^^^^^^^^^^^^^^^^^^^^^^^^^^^^^^^^^^^^
  File "/opt/airflow/dags/data-ingestion-dag.py", line 62, in validate_data
    batch = context.get_batch(batch_kwargs, expectation_suite_name)
            ^^^^^^^^^^^^^^^^^
AttributeError: 'FileDataContext' object has no attribute 'get_batch'. Did you mean: '_get_batch_v2'?
[2024-05-17T19:19:42.670+0000] {taskinstance.py:1206} INFO - Marking task as FAILED. dag_id=data_ingestion_pipelines_2, task_id=validate_data, run_id=manual__2024-05-17T12:31:17.083416+00:00, execution_date=20240517T123117, start_date=20240517T191941, end_date=20240517T191942
[2024-05-17T19:19:42.695+0000] {standard_task_runner.py:110} ERROR - Failed to execute job 18 for task validate_data ('FileDataContext' object has no attribute 'get_batch'; 4793)
[2024-05-17T19:19:42.722+0000] {local_task_job_runner.py:240} INFO - Task exited with return code 1
[2024-05-17T19:19:42.742+0000] {local_task_job_runner.py:222} INFO - ::endgroup::
