[2024-05-16T23:34:42.095+0000] {local_task_job_runner.py:120} INFO - ::group::Pre task execution logs
[2024-05-16T23:34:42.142+0000] {taskinstance.py:2076} INFO - Dependencies all met for dep_context=non-requeueable deps ti=<TaskInstance: data_ingestion_pipelines_2.validate_data scheduled__2024-05-15T00:00:00+00:00 [queued]>
[2024-05-16T23:34:42.154+0000] {taskinstance.py:2076} INFO - Dependencies all met for dep_context=requeueable deps ti=<TaskInstance: data_ingestion_pipelines_2.validate_data scheduled__2024-05-15T00:00:00+00:00 [queued]>
[2024-05-16T23:34:42.157+0000] {taskinstance.py:2306} INFO - Starting attempt 6 of 6
[2024-05-16T23:34:42.174+0000] {taskinstance.py:2330} INFO - Executing <Task(PythonOperator): validate_data> on 2024-05-15 00:00:00+00:00
[2024-05-16T23:34:42.184+0000] {warnings.py:110} WARNING - /home/***/.local/lib/python3.12/site-packages/***/task/task_runner/standard_task_runner.py:61: DeprecationWarning: This process (pid=1216) is multi-threaded, use of fork() may lead to deadlocks in the child.
  pid = os.fork()

[2024-05-16T23:34:42.187+0000] {standard_task_runner.py:63} INFO - Started process 1228 to run task
[2024-05-16T23:34:42.186+0000] {standard_task_runner.py:90} INFO - Running: ['***', 'tasks', 'run', 'data_ingestion_pipelines_2', 'validate_data', 'scheduled__2024-05-15T00:00:00+00:00', '--job-id', '12', '--raw', '--subdir', 'DAGS_FOLDER/data-ingestion-dag.py', '--cfg-path', '/tmp/tmpr_flcwdb']
[2024-05-16T23:34:42.188+0000] {standard_task_runner.py:91} INFO - Job 12: Subtask validate_data
[2024-05-16T23:34:42.253+0000] {task_command.py:426} INFO - Running <TaskInstance: data_ingestion_pipelines_2.validate_data scheduled__2024-05-15T00:00:00+00:00 [running]> on host 2fc1c160da1e
[2024-05-16T23:34:42.372+0000] {taskinstance.py:2648} INFO - Exporting env vars: AIRFLOW_CTX_DAG_OWNER='***' AIRFLOW_CTX_DAG_ID='data_ingestion_pipelines_2' AIRFLOW_CTX_TASK_ID='validate_data' AIRFLOW_CTX_EXECUTION_DATE='2024-05-15T00:00:00+00:00' AIRFLOW_CTX_TRY_NUMBER='6' AIRFLOW_CTX_DAG_RUN_ID='scheduled__2024-05-15T00:00:00+00:00'
[2024-05-16T23:34:42.374+0000] {taskinstance.py:430} INFO - ::endgroup::
[2024-05-16T23:34:42.404+0000] {logging_mixin.py:188} INFO - file_path in validate_data is  /opt/***/dags/raw-data/data_part_1.csv
[2024-05-16T23:34:42.405+0000] {logging_mixin.py:188} INFO - data_asset_name is  data_part_1
[2024-05-16T23:34:42.421+0000] {taskinstance.py:441} INFO - ::group::Post task execution logs
[2024-05-16T23:34:42.422+0000] {taskinstance.py:2905} ERROR - Task failed with exception
Traceback (most recent call last):
  File "/home/airflow/.local/lib/python3.12/site-packages/airflow/models/taskinstance.py", line 465, in _execute_task
    result = _execute_callable(context=context, **execute_callable_kwargs)
             ^^^^^^^^^^^^^^^^^^^^^^^^^^^^^^^^^^^^^^^^^^^^^^^^^^^^^^^^^^^^^
  File "/home/airflow/.local/lib/python3.12/site-packages/airflow/models/taskinstance.py", line 432, in _execute_callable
    return execute_callable(context=context, **execute_callable_kwargs)
           ^^^^^^^^^^^^^^^^^^^^^^^^^^^^^^^^^^^^^^^^^^^^^^^^^^^^^^^^^^^^
  File "/home/airflow/.local/lib/python3.12/site-packages/airflow/models/baseoperator.py", line 400, in wrapper
    return func(self, *args, **kwargs)
           ^^^^^^^^^^^^^^^^^^^^^^^^^^^
  File "/home/airflow/.local/lib/python3.12/site-packages/airflow/operators/python.py", line 235, in execute
    return_value = self.execute_callable()
                   ^^^^^^^^^^^^^^^^^^^^^^^
  File "/home/airflow/.local/lib/python3.12/site-packages/airflow/operators/python.py", line 252, in execute_callable
    return self.python_callable(*self.op_args, **self.op_kwargs)
           ^^^^^^^^^^^^^^^^^^^^^^^^^^^^^^^^^^^^^^^^^^^^^^^^^^^^^
  File "/opt/airflow/dags/data-ingestion-dag.py", line 59, in validate_data
    batch = context.get_batch(batch_kwargs, 'ex_dyali')
            ^^^^^^^
NameError: name 'context' is not defined
[2024-05-16T23:34:42.439+0000] {taskinstance.py:1206} INFO - Marking task as FAILED. dag_id=data_ingestion_pipelines_2, task_id=validate_data, run_id=scheduled__2024-05-15T00:00:00+00:00, execution_date=20240515T000000, start_date=20240516T233442, end_date=20240516T233442
[2024-05-16T23:34:42.456+0000] {standard_task_runner.py:110} ERROR - Failed to execute job 12 for task validate_data (name 'context' is not defined; 1228)
[2024-05-16T23:34:42.482+0000] {local_task_job_runner.py:240} INFO - Task exited with return code 1
[2024-05-16T23:34:42.517+0000] {taskinstance.py:3498} INFO - 0 downstream tasks scheduled from follow-on schedule check
[2024-05-16T23:34:42.523+0000] {local_task_job_runner.py:222} INFO - ::endgroup::
