[2024-05-16T23:58:29.365+0000] {local_task_job_runner.py:120} INFO - ::group::Pre task execution logs
[2024-05-16T23:58:29.407+0000] {taskinstance.py:2076} INFO - Dependencies all met for dep_context=non-requeueable deps ti=<TaskInstance: data_ingestion_pipelines_2.validate_data scheduled__2024-05-15T00:00:00+00:00 [queued]>
[2024-05-16T23:58:29.419+0000] {taskinstance.py:2076} INFO - Dependencies all met for dep_context=requeueable deps ti=<TaskInstance: data_ingestion_pipelines_2.validate_data scheduled__2024-05-15T00:00:00+00:00 [queued]>
[2024-05-16T23:58:29.422+0000] {taskinstance.py:2306} INFO - Starting attempt 11 of 11
[2024-05-16T23:58:29.441+0000] {taskinstance.py:2330} INFO - Executing <Task(PythonOperator): validate_data> on 2024-05-15 00:00:00+00:00
[2024-05-16T23:58:29.451+0000] {warnings.py:110} WARNING - /home/***/.local/lib/python3.12/site-packages/***/task/task_runner/standard_task_runner.py:61: DeprecationWarning: This process (pid=2785) is multi-threaded, use of fork() may lead to deadlocks in the child.
  pid = os.fork()

[2024-05-16T23:58:29.454+0000] {standard_task_runner.py:63} INFO - Started process 2795 to run task
[2024-05-16T23:58:29.453+0000] {standard_task_runner.py:90} INFO - Running: ['***', 'tasks', 'run', 'data_ingestion_pipelines_2', 'validate_data', 'scheduled__2024-05-15T00:00:00+00:00', '--job-id', '17', '--raw', '--subdir', 'DAGS_FOLDER/data-ingestion-dag.py', '--cfg-path', '/tmp/tmp5mzb3212']
[2024-05-16T23:58:29.455+0000] {standard_task_runner.py:91} INFO - Job 17: Subtask validate_data
[2024-05-16T23:58:29.530+0000] {task_command.py:426} INFO - Running <TaskInstance: data_ingestion_pipelines_2.validate_data scheduled__2024-05-15T00:00:00+00:00 [running]> on host 2fc1c160da1e
[2024-05-16T23:58:29.720+0000] {taskinstance.py:2648} INFO - Exporting env vars: AIRFLOW_CTX_DAG_OWNER='***' AIRFLOW_CTX_DAG_ID='data_ingestion_pipelines_2' AIRFLOW_CTX_TASK_ID='validate_data' AIRFLOW_CTX_EXECUTION_DATE='2024-05-15T00:00:00+00:00' AIRFLOW_CTX_TRY_NUMBER='11' AIRFLOW_CTX_DAG_RUN_ID='scheduled__2024-05-15T00:00:00+00:00'
[2024-05-16T23:58:29.722+0000] {taskinstance.py:430} INFO - ::endgroup::
[2024-05-16T23:58:29.797+0000] {taskinstance.py:441} INFO - ::group::Post task execution logs
[2024-05-16T23:58:29.798+0000] {taskinstance.py:2905} ERROR - Task failed with exception
Traceback (most recent call last):
  File "/home/airflow/.local/lib/python3.12/site-packages/great_expectations/data_context/data_context/file_data_context.py", line 198, in _load_file_backed_project_config
    with open(path_to_yml) as data:
         ^^^^^^^^^^^^^^^^^
FileNotFoundError: [Errno 2] No such file or directory: '/opt/airflow/C:\\Users\\salma elyagoubi\\error418\\docker\\airflow\\gx/great_expectations.yml'

During handling of the above exception, another exception occurred:

Traceback (most recent call last):
  File "/home/airflow/.local/lib/python3.12/site-packages/airflow/models/taskinstance.py", line 465, in _execute_task
    result = _execute_callable(context=context, **execute_callable_kwargs)
             ^^^^^^^^^^^^^^^^^^^^^^^^^^^^^^^^^^^^^^^^^^^^^^^^^^^^^^^^^^^^^
  File "/home/airflow/.local/lib/python3.12/site-packages/airflow/models/taskinstance.py", line 432, in _execute_callable
    return execute_callable(context=context, **execute_callable_kwargs)
           ^^^^^^^^^^^^^^^^^^^^^^^^^^^^^^^^^^^^^^^^^^^^^^^^^^^^^^^^^^^^
  File "/home/airflow/.local/lib/python3.12/site-packages/airflow/models/baseoperator.py", line 400, in wrapper
    return func(self, *args, **kwargs)
           ^^^^^^^^^^^^^^^^^^^^^^^^^^^
  File "/home/airflow/.local/lib/python3.12/site-packages/airflow/operators/python.py", line 235, in execute
    return_value = self.execute_callable()
                   ^^^^^^^^^^^^^^^^^^^^^^^
  File "/home/airflow/.local/lib/python3.12/site-packages/airflow/operators/python.py", line 252, in execute_callable
    return self.python_callable(*self.op_args, **self.op_kwargs)
           ^^^^^^^^^^^^^^^^^^^^^^^^^^^^^^^^^^^^^^^^^^^^^^^^^^^^^
  File "/opt/airflow/dags/data-ingestion-dag.py", line 54, in validate_data
    context = ge.data_context.DataContext(context_root_dir=GE_DIRECTORY)
              ^^^^^^^^^^^^^^^^^^^^^^^^^^^^^^^^^^^^^^^^^^^^^^^^^^^^^^^^^^
  File "/home/airflow/.local/lib/python3.12/site-packages/great_expectations/data_context/data_context/data_context.py", line 129, in DataContext
    project_config = FileDataContext._load_file_backed_project_config(
                     ^^^^^^^^^^^^^^^^^^^^^^^^^^^^^^^^^^^^^^^^^^^^^^^^^
  File "/home/airflow/.local/lib/python3.12/site-packages/great_expectations/data_context/data_context/file_data_context.py", line 210, in _load_file_backed_project_config
    raise gx_exceptions.ConfigNotFoundError()
great_expectations.exceptions.exceptions.ConfigNotFoundError: Error: No gx directory was found here!
    - Please check that you are in the correct directory or have specified the correct directory.
    - If you have never run Great Expectations in this project, please run `great_expectations init` to get started.

[2024-05-16T23:58:29.816+0000] {taskinstance.py:1206} INFO - Marking task as FAILED. dag_id=data_ingestion_pipelines_2, task_id=validate_data, run_id=scheduled__2024-05-15T00:00:00+00:00, execution_date=20240515T000000, start_date=20240516T235829, end_date=20240516T235829
[2024-05-16T23:58:29.841+0000] {standard_task_runner.py:110} ERROR - Failed to execute job 17 for task validate_data (Error: No gx directory was found here!
    - Please check that you are in the correct directory or have specified the correct directory.
    - If you have never run Great Expectations in this project, please run `great_expectations init` to get started.
; 2795)
[2024-05-16T23:58:29.870+0000] {local_task_job_runner.py:240} INFO - Task exited with return code 1
[2024-05-16T23:58:29.902+0000] {taskinstance.py:3498} INFO - 0 downstream tasks scheduled from follow-on schedule check
[2024-05-16T23:58:29.908+0000] {local_task_job_runner.py:222} INFO - ::endgroup::
