[2024-05-18T01:21:10.031+0000] {local_task_job_runner.py:120} INFO - ::group::Pre task execution logs
[2024-05-18T01:21:10.239+0000] {taskinstance.py:2076} INFO - Dependencies all met for dep_context=non-requeueable deps ti=<TaskInstance: data_ingestion_pipelines_2.validate_data scheduled__2024-05-17T00:00:00+00:00 [queued]>
[2024-05-18T01:21:10.277+0000] {taskinstance.py:2076} INFO - Dependencies all met for dep_context=requeueable deps ti=<TaskInstance: data_ingestion_pipelines_2.validate_data scheduled__2024-05-17T00:00:00+00:00 [queued]>
[2024-05-18T01:21:10.279+0000] {taskinstance.py:2306} INFO - Starting attempt 4 of 4
[2024-05-18T01:21:10.330+0000] {taskinstance.py:2330} INFO - Executing <Task(PythonOperator): validate_data> on 2024-05-17 00:00:00+00:00
[2024-05-18T01:21:10.349+0000] {warnings.py:110} WARNING - /home/***/.local/lib/python3.12/site-packages/***/task/task_runner/standard_task_runner.py:61: DeprecationWarning: This process (pid=689) is multi-threaded, use of fork() may lead to deadlocks in the child.
  pid = os.fork()

[2024-05-18T01:21:10.353+0000] {standard_task_runner.py:63} INFO - Started process 713 to run task
[2024-05-18T01:21:10.353+0000] {standard_task_runner.py:90} INFO - Running: ['***', 'tasks', 'run', 'data_ingestion_pipelines_2', 'validate_data', 'scheduled__2024-05-17T00:00:00+00:00', '--job-id', '148', '--raw', '--subdir', 'DAGS_FOLDER/data-ingestion-dag.py', '--cfg-path', '/tmp/tmpa5vg6uaa']
[2024-05-18T01:21:10.357+0000] {standard_task_runner.py:91} INFO - Job 148: Subtask validate_data
[2024-05-18T01:21:10.464+0000] {task_command.py:426} INFO - Running <TaskInstance: data_ingestion_pipelines_2.validate_data scheduled__2024-05-17T00:00:00+00:00 [running]> on host e512d0910ba5
[2024-05-18T01:21:10.681+0000] {taskinstance.py:2648} INFO - Exporting env vars: AIRFLOW_CTX_DAG_OWNER='***' AIRFLOW_CTX_DAG_ID='data_ingestion_pipelines_2' AIRFLOW_CTX_TASK_ID='validate_data' AIRFLOW_CTX_EXECUTION_DATE='2024-05-17T00:00:00+00:00' AIRFLOW_CTX_TRY_NUMBER='4' AIRFLOW_CTX_DAG_RUN_ID='scheduled__2024-05-17T00:00:00+00:00'
[2024-05-18T01:21:10.684+0000] {taskinstance.py:430} INFO - ::endgroup::
[2024-05-18T01:21:10.733+0000] {logging_mixin.py:188} INFO - file_path in validate_data is  /opt/***/dags/raw-data/data_part_1.csv
[2024-05-18T01:21:10.733+0000] {logging_mixin.py:188} INFO - data_asset_name is  data_part_1
[2024-05-18T01:21:10.767+0000] {logging_mixin.py:188} INFO - Data types after reading CSV:
[2024-05-18T01:21:10.770+0000] {logging_mixin.py:188} INFO -  ph                 float64
Hardness           float64
Solids             float64
Chloramines        float64
Sulfate            float64
Conductivity       float64
Organic_carbon     float64
Trihalomethanes    float64
Turbidity          float64
Potability           Int64
dtype: object
[2024-05-18T01:21:10.851+0000] {warnings.py:110} WARNING - /home/***/.local/lib/python3.12/site-packages/great_expectations/data_context/data_context/base_data_context.py:158: DeprecationWarning: DataContext and BaseDataContext are deprecated as of v0.17.10 and will be removed in v0.20. Please use gx.get_context instead.
  warnings.warn(

[2024-05-18T01:21:10.947+0000] {file_data_context.py:222} INFO - FileDataContext loading fluent config
[2024-05-18T01:21:10.992+0000] {config.py:187} INFO - Loading 'datasources' ->
[]
[2024-05-18T01:21:11.511+0000] {taskinstance.py:441} INFO - ::group::Post task execution logs
[2024-05-18T01:21:11.512+0000] {taskinstance.py:2905} ERROR - Task failed with exception
Traceback (most recent call last):
  File "/home/airflow/.local/lib/python3.12/site-packages/airflow/models/taskinstance.py", line 465, in _execute_task
    result = _execute_callable(context=context, **execute_callable_kwargs)
             ^^^^^^^^^^^^^^^^^^^^^^^^^^^^^^^^^^^^^^^^^^^^^^^^^^^^^^^^^^^^^
  File "/home/airflow/.local/lib/python3.12/site-packages/airflow/models/taskinstance.py", line 432, in _execute_callable
    return execute_callable(context=context, **execute_callable_kwargs)
           ^^^^^^^^^^^^^^^^^^^^^^^^^^^^^^^^^^^^^^^^^^^^^^^^^^^^^^^^^^^^
  File "/home/airflow/.local/lib/python3.12/site-packages/airflow/models/baseoperator.py", line 400, in wrapper
    return func(self, *args, **kwargs)
           ^^^^^^^^^^^^^^^^^^^^^^^^^^^
  File "/home/airflow/.local/lib/python3.12/site-packages/airflow/operators/python.py", line 235, in execute
    return_value = self.execute_callable()
                   ^^^^^^^^^^^^^^^^^^^^^^^
  File "/home/airflow/.local/lib/python3.12/site-packages/airflow/operators/python.py", line 252, in execute_callable
    return self.python_callable(*self.op_args, **self.op_kwargs)
           ^^^^^^^^^^^^^^^^^^^^^^^^^^^^^^^^^^^^^^^^^^^^^^^^^^^^^
  File "/opt/airflow/dags/data-ingestion-dag.py", line 70, in validate_data
    expectation_suite = context.get_expectation_suite(expectation_suite_name)
                        ^^^^^^^^^^^^^^^^^^^^^^^^^^^^^^^^^^^^^^^^^^^^^^^^^^^^^
  File "/home/airflow/.local/lib/python3.12/site-packages/great_expectations/data_context/data_context/abstract_data_context.py", line 3022, in get_expectation_suite
    dict, self.expectations_store.get(key)
          ^^^^^^^^^^^^^^^^^^^^^^^^^^^^^^^^
  File "/home/airflow/.local/lib/python3.12/site-packages/great_expectations/data_context/store/expectations_store.py", line 210, in get
    return super().get(key)  # type: ignore[return-value]
           ^^^^^^^^^^^^^^^^
  File "/home/airflow/.local/lib/python3.12/site-packages/great_expectations/data_context/store/store.py", line 210, in get
    return self.deserialize(value)
           ^^^^^^^^^^^^^^^^^^^^^^^
  File "/home/airflow/.local/lib/python3.12/site-packages/great_expectations/data_context/store/expectations_store.py", line 236, in deserialize
    return self._expectationSuiteSchema.loads(value)
           ^^^^^^^^^^^^^^^^^^^^^^^^^^^^^^^^^^^^^^^^^
  File "/home/airflow/.local/lib/python3.12/site-packages/marshmallow/schema.py", line 756, in loads
    data = self.opts.render_module.loads(json_data, **kwargs)
           ^^^^^^^^^^^^^^^^^^^^^^^^^^^^^^^^^^^^^^^^^^^^^^^^^^
  File "/usr/local/lib/python3.12/json/__init__.py", line 346, in loads
    return _default_decoder.decode(s)
           ^^^^^^^^^^^^^^^^^^^^^^^^^^
  File "/usr/local/lib/python3.12/json/decoder.py", line 340, in decode
    raise JSONDecodeError("Extra data", s, end)
json.decoder.JSONDecodeError: Extra data: line 216 column 1 (char 4931)
[2024-05-18T01:21:11.533+0000] {taskinstance.py:1206} INFO - Marking task as FAILED. dag_id=data_ingestion_pipelines_2, task_id=validate_data, run_id=scheduled__2024-05-17T00:00:00+00:00, execution_date=20240517T000000, start_date=20240518T012110, end_date=20240518T012111
[2024-05-18T01:21:11.557+0000] {standard_task_runner.py:110} ERROR - Failed to execute job 148 for task validate_data (Extra data: line 216 column 1 (char 4931); 713)
[2024-05-18T01:21:11.575+0000] {local_task_job_runner.py:240} INFO - Task exited with return code 1
[2024-05-18T01:21:11.615+0000] {taskinstance.py:3498} INFO - 0 downstream tasks scheduled from follow-on schedule check
[2024-05-18T01:21:11.623+0000] {local_task_job_runner.py:222} INFO - ::endgroup::
