[2024-05-17T11:49:17.522+0000] {local_task_job_runner.py:120} INFO - ::group::Pre task execution logs
[2024-05-17T11:49:17.558+0000] {taskinstance.py:2076} INFO - Dependencies all met for dep_context=non-requeueable deps ti=<TaskInstance: data_ingestion_pipelines_2.validate_data manual__2024-05-17T11:30:28.713644+00:00 [queued]>
[2024-05-17T11:49:17.568+0000] {taskinstance.py:2076} INFO - Dependencies all met for dep_context=requeueable deps ti=<TaskInstance: data_ingestion_pipelines_2.validate_data manual__2024-05-17T11:30:28.713644+00:00 [queued]>
[2024-05-17T11:49:17.569+0000] {taskinstance.py:2306} INFO - Starting attempt 4 of 4
[2024-05-17T11:49:17.585+0000] {taskinstance.py:2330} INFO - Executing <Task(PythonOperator): validate_data> on 2024-05-17 11:30:28.713644+00:00
[2024-05-17T11:49:17.592+0000] {warnings.py:110} WARNING - /home/***/.local/lib/python3.12/site-packages/***/task/task_runner/standard_task_runner.py:61: DeprecationWarning: This process (pid=1570) is multi-threaded, use of fork() may lead to deadlocks in the child.
  pid = os.fork()

[2024-05-17T11:49:17.594+0000] {standard_task_runner.py:63} INFO - Started process 1582 to run task
[2024-05-17T11:49:17.594+0000] {standard_task_runner.py:90} INFO - Running: ['***', 'tasks', 'run', 'data_ingestion_pipelines_2', 'validate_data', 'manual__2024-05-17T11:30:28.713644+00:00', '--job-id', '14', '--raw', '--subdir', 'DAGS_FOLDER/data-ingestion-dag.py', '--cfg-path', '/tmp/tmpyptjl1w3']
[2024-05-17T11:49:17.595+0000] {standard_task_runner.py:91} INFO - Job 14: Subtask validate_data
[2024-05-17T11:49:17.647+0000] {task_command.py:426} INFO - Running <TaskInstance: data_ingestion_pipelines_2.validate_data manual__2024-05-17T11:30:28.713644+00:00 [running]> on host 11a40e6e6344
[2024-05-17T11:49:17.740+0000] {taskinstance.py:2648} INFO - Exporting env vars: AIRFLOW_CTX_DAG_OWNER='***' AIRFLOW_CTX_DAG_ID='data_ingestion_pipelines_2' AIRFLOW_CTX_TASK_ID='validate_data' AIRFLOW_CTX_EXECUTION_DATE='2024-05-17T11:30:28.713644+00:00' AIRFLOW_CTX_TRY_NUMBER='4' AIRFLOW_CTX_DAG_RUN_ID='manual__2024-05-17T11:30:28.713644+00:00'
[2024-05-17T11:49:17.741+0000] {taskinstance.py:430} INFO - ::endgroup::
[2024-05-17T11:49:17.769+0000] {logging_mixin.py:188} INFO - file_path in validate_data is  /opt/***/dags/raw-data/data_part_5.csv
[2024-05-17T11:49:17.770+0000] {logging_mixin.py:188} INFO - data_asset_name is  data_part_5
[2024-05-17T11:49:17.833+0000] {warnings.py:110} WARNING - /home/***/.local/lib/python3.12/site-packages/great_expectations/data_context/data_context/base_data_context.py:158: DeprecationWarning: DataContext and BaseDataContext are deprecated as of v0.17.10 and will be removed in v0.20. Please use gx.get_context instead.
  warnings.warn(

[2024-05-17T11:49:17.918+0000] {warnings.py:110} WARNING - /home/***/.local/lib/python3.12/site-packages/great_expectations/data_context/data_context/serializable_data_context.py:225: UserWarning: Warning. An existing `great_expectations.yml` was found here: /opt/***/gx.
    - No action was taken.
  warnings.warn(message)

[2024-05-17T11:49:17.921+0000] {warnings.py:110} WARNING - /home/***/.local/lib/python3.12/site-packages/great_expectations/data_context/data_context/serializable_data_context.py:235: UserWarning: Warning. An existing `config_variables.yml` was found here: /opt/***/gx/uncommitted.
    - No action was taken.
  warnings.warn(message)

[2024-05-17T11:49:17.934+0000] {file_data_context.py:222} INFO - FileDataContext loading fluent config
[2024-05-17T11:49:17.985+0000] {config.py:187} INFO - Loading 'datasources' ->
[]
[2024-05-17T11:49:18.109+0000] {taskinstance.py:441} INFO - ::group::Post task execution logs
[2024-05-17T11:49:18.111+0000] {taskinstance.py:2905} ERROR - Task failed with exception
Traceback (most recent call last):
  File "/home/airflow/.local/lib/python3.12/site-packages/airflow/models/taskinstance.py", line 465, in _execute_task
    result = _execute_callable(context=context, **execute_callable_kwargs)
             ^^^^^^^^^^^^^^^^^^^^^^^^^^^^^^^^^^^^^^^^^^^^^^^^^^^^^^^^^^^^^
  File "/home/airflow/.local/lib/python3.12/site-packages/airflow/models/taskinstance.py", line 432, in _execute_callable
    return execute_callable(context=context, **execute_callable_kwargs)
           ^^^^^^^^^^^^^^^^^^^^^^^^^^^^^^^^^^^^^^^^^^^^^^^^^^^^^^^^^^^^
  File "/home/airflow/.local/lib/python3.12/site-packages/airflow/models/baseoperator.py", line 400, in wrapper
    return func(self, *args, **kwargs)
           ^^^^^^^^^^^^^^^^^^^^^^^^^^^
  File "/home/airflow/.local/lib/python3.12/site-packages/airflow/operators/python.py", line 235, in execute
    return_value = self.execute_callable()
                   ^^^^^^^^^^^^^^^^^^^^^^^
  File "/home/airflow/.local/lib/python3.12/site-packages/airflow/operators/python.py", line 252, in execute_callable
    return self.python_callable(*self.op_args, **self.op_kwargs)
           ^^^^^^^^^^^^^^^^^^^^^^^^^^^^^^^^^^^^^^^^^^^^^^^^^^^^^
  File "/opt/airflow/dags/data-ingestion-dag.py", line 59, in validate_data
    expectation_suite = context.get_expectation_suite(expectation_suite_name)
                        ^^^^^^^^^^^^^^^^^^^^^^^^^^^^^^^^^^^^^^^^^^^^^^^^^^^^^
  File "/home/airflow/.local/lib/python3.12/site-packages/great_expectations/data_context/data_context/abstract_data_context.py", line 3033, in get_expectation_suite
    raise gx_exceptions.DataContextError(
great_expectations.exceptions.exceptions.DataContextError: expectation_suite ex_dyali not found
[2024-05-17T11:49:18.126+0000] {taskinstance.py:1206} INFO - Marking task as FAILED. dag_id=data_ingestion_pipelines_2, task_id=validate_data, run_id=manual__2024-05-17T11:30:28.713644+00:00, execution_date=20240517T113028, start_date=20240517T114917, end_date=20240517T114918
[2024-05-17T11:49:18.144+0000] {standard_task_runner.py:110} ERROR - Failed to execute job 14 for task validate_data (expectation_suite ex_dyali not found; 1582)
[2024-05-17T11:49:18.170+0000] {local_task_job_runner.py:240} INFO - Task exited with return code 1
[2024-05-17T11:49:18.184+0000] {local_task_job_runner.py:222} INFO - ::endgroup::
