[2024-05-17T12:06:38.743+0000] {local_task_job_runner.py:120} INFO - ::group::Pre task execution logs
[2024-05-17T12:06:38.793+0000] {taskinstance.py:2076} INFO - Dependencies all met for dep_context=non-requeueable deps ti=<TaskInstance: data_ingestion_pipelines_2.validate_data manual__2024-05-17T12:06:23.700839+00:00 [queued]>
[2024-05-17T12:06:38.807+0000] {taskinstance.py:2076} INFO - Dependencies all met for dep_context=requeueable deps ti=<TaskInstance: data_ingestion_pipelines_2.validate_data manual__2024-05-17T12:06:23.700839+00:00 [queued]>
[2024-05-17T12:06:38.808+0000] {taskinstance.py:2306} INFO - Starting attempt 1 of 1
[2024-05-17T12:06:38.834+0000] {taskinstance.py:2330} INFO - Executing <Task(PythonOperator): validate_data> on 2024-05-17 12:06:23.700839+00:00
[2024-05-17T12:06:38.845+0000] {warnings.py:110} WARNING - /home/***/.local/lib/python3.12/site-packages/***/task/task_runner/standard_task_runner.py:61: DeprecationWarning: This process (pid=295) is multi-threaded, use of fork() may lead to deadlocks in the child.
  pid = os.fork()

[2024-05-17T12:06:38.849+0000] {standard_task_runner.py:63} INFO - Started process 316 to run task
[2024-05-17T12:06:38.849+0000] {standard_task_runner.py:90} INFO - Running: ['***', 'tasks', 'run', 'data_ingestion_pipelines_2', 'validate_data', 'manual__2024-05-17T12:06:23.700839+00:00', '--job-id', '6', '--raw', '--subdir', 'DAGS_FOLDER/data-ingestion-dag.py', '--cfg-path', '/tmp/tmp__dup0g_']
[2024-05-17T12:06:38.851+0000] {standard_task_runner.py:91} INFO - Job 6: Subtask validate_data
[2024-05-17T12:06:38.931+0000] {task_command.py:426} INFO - Running <TaskInstance: data_ingestion_pipelines_2.validate_data manual__2024-05-17T12:06:23.700839+00:00 [running]> on host baf2bcf863ea
[2024-05-17T12:06:39.060+0000] {taskinstance.py:2648} INFO - Exporting env vars: AIRFLOW_CTX_DAG_OWNER='***' AIRFLOW_CTX_DAG_ID='data_ingestion_pipelines_2' AIRFLOW_CTX_TASK_ID='validate_data' AIRFLOW_CTX_EXECUTION_DATE='2024-05-17T12:06:23.700839+00:00' AIRFLOW_CTX_TRY_NUMBER='1' AIRFLOW_CTX_DAG_RUN_ID='manual__2024-05-17T12:06:23.700839+00:00'
[2024-05-17T12:06:39.062+0000] {taskinstance.py:430} INFO - ::endgroup::
[2024-05-17T12:06:39.095+0000] {logging_mixin.py:188} INFO - file_path in validate_data is  /opt/***/dags/raw-data/data_part_9.csv
[2024-05-17T12:06:39.096+0000] {logging_mixin.py:188} INFO - data_asset_name is  data_part_9
[2024-05-17T12:06:39.166+0000] {warnings.py:110} WARNING - /home/***/.local/lib/python3.12/site-packages/great_expectations/data_context/data_context/base_data_context.py:158: DeprecationWarning: DataContext and BaseDataContext are deprecated as of v0.17.10 and will be removed in v0.20. Please use gx.get_context instead.
  warnings.warn(

[2024-05-17T12:06:39.235+0000] {warnings.py:110} WARNING - /home/***/.local/lib/python3.12/site-packages/great_expectations/data_context/data_context/serializable_data_context.py:225: UserWarning: Warning. An existing `great_expectations.yml` was found here: /opt/***/gx.
    - No action was taken.
  warnings.warn(message)

[2024-05-17T12:06:39.238+0000] {warnings.py:110} WARNING - /home/***/.local/lib/python3.12/site-packages/great_expectations/data_context/data_context/serializable_data_context.py:235: UserWarning: Warning. An existing `config_variables.yml` was found here: /opt/***/gx/uncommitted.
    - No action was taken.
  warnings.warn(message)

[2024-05-17T12:06:39.246+0000] {file_data_context.py:222} INFO - FileDataContext loading fluent config
[2024-05-17T12:06:39.277+0000] {config.py:187} INFO - Loading 'datasources' ->
[]
[2024-05-17T12:06:39.387+0000] {taskinstance.py:441} INFO - ::group::Post task execution logs
[2024-05-17T12:06:39.388+0000] {taskinstance.py:2905} ERROR - Task failed with exception
Traceback (most recent call last):
  File "/home/airflow/.local/lib/python3.12/site-packages/airflow/models/taskinstance.py", line 465, in _execute_task
    result = _execute_callable(context=context, **execute_callable_kwargs)
             ^^^^^^^^^^^^^^^^^^^^^^^^^^^^^^^^^^^^^^^^^^^^^^^^^^^^^^^^^^^^^
  File "/home/airflow/.local/lib/python3.12/site-packages/airflow/models/taskinstance.py", line 432, in _execute_callable
    return execute_callable(context=context, **execute_callable_kwargs)
           ^^^^^^^^^^^^^^^^^^^^^^^^^^^^^^^^^^^^^^^^^^^^^^^^^^^^^^^^^^^^
  File "/home/airflow/.local/lib/python3.12/site-packages/airflow/models/baseoperator.py", line 400, in wrapper
    return func(self, *args, **kwargs)
           ^^^^^^^^^^^^^^^^^^^^^^^^^^^
  File "/home/airflow/.local/lib/python3.12/site-packages/airflow/operators/python.py", line 235, in execute
    return_value = self.execute_callable()
                   ^^^^^^^^^^^^^^^^^^^^^^^
  File "/home/airflow/.local/lib/python3.12/site-packages/airflow/operators/python.py", line 252, in execute_callable
    return self.python_callable(*self.op_args, **self.op_kwargs)
           ^^^^^^^^^^^^^^^^^^^^^^^^^^^^^^^^^^^^^^^^^^^^^^^^^^^^^
  File "/opt/airflow/dags/data-ingestion-dag.py", line 59, in validate_data
    expectation_suite = context.get_expectation_suite(expectation_suite_name)
                        ^^^^^^^^^^^^^^^^^^^^^^^^^^^^^^^^^^^^^^^^^^^^^^^^^^^^^
  File "/home/airflow/.local/lib/python3.12/site-packages/great_expectations/data_context/data_context/abstract_data_context.py", line 3033, in get_expectation_suite
    raise gx_exceptions.DataContextError(
great_expectations.exceptions.exceptions.DataContextError: expectation_suite ex_dyali not found
[2024-05-17T12:06:39.402+0000] {taskinstance.py:1206} INFO - Marking task as FAILED. dag_id=data_ingestion_pipelines_2, task_id=validate_data, run_id=manual__2024-05-17T12:06:23.700839+00:00, execution_date=20240517T120623, start_date=20240517T120638, end_date=20240517T120639
[2024-05-17T12:06:39.420+0000] {standard_task_runner.py:110} ERROR - Failed to execute job 6 for task validate_data (expectation_suite ex_dyali not found; 316)
[2024-05-17T12:06:39.466+0000] {local_task_job_runner.py:240} INFO - Task exited with return code 1
[2024-05-17T12:06:39.501+0000] {taskinstance.py:3498} INFO - 0 downstream tasks scheduled from follow-on schedule check
[2024-05-17T12:06:39.508+0000] {local_task_job_runner.py:222} INFO - ::endgroup::
