[2024-05-16T21:06:11.494+0000] {local_task_job_runner.py:120} INFO - ::group::Pre task execution logs
[2024-05-16T21:06:11.529+0000] {taskinstance.py:2076} INFO - Dependencies all met for dep_context=non-requeueable deps ti=<TaskInstance: data_ingestion.read_data scheduled__2024-05-16T21:04:00+00:00 [queued]>
[2024-05-16T21:06:11.538+0000] {taskinstance.py:2076} INFO - Dependencies all met for dep_context=requeueable deps ti=<TaskInstance: data_ingestion.read_data scheduled__2024-05-16T21:04:00+00:00 [queued]>
[2024-05-16T21:06:11.540+0000] {taskinstance.py:2306} INFO - Starting attempt 2 of 2
[2024-05-16T21:06:11.553+0000] {taskinstance.py:2330} INFO - Executing <Task(PythonOperator): read_data> on 2024-05-16 21:04:00+00:00
[2024-05-16T21:06:11.561+0000] {warnings.py:110} WARNING - /home/***/.local/lib/python3.12/site-packages/***/task/task_runner/standard_task_runner.py:61: DeprecationWarning: This process (pid=564) is multi-threaded, use of fork() may lead to deadlocks in the child.
  pid = os.fork()

[2024-05-16T21:06:11.562+0000] {standard_task_runner.py:63} INFO - Started process 574 to run task
[2024-05-16T21:06:11.562+0000] {standard_task_runner.py:90} INFO - Running: ['***', 'tasks', 'run', 'data_ingestion', 'read_data', 'scheduled__2024-05-16T21:04:00+00:00', '--job-id', '16', '--raw', '--subdir', 'DAGS_FOLDER/first_dag.py', '--cfg-path', '/tmp/tmpwivfsejp']
[2024-05-16T21:06:11.563+0000] {standard_task_runner.py:91} INFO - Job 16: Subtask read_data
[2024-05-16T21:06:11.612+0000] {task_command.py:426} INFO - Running <TaskInstance: data_ingestion.read_data scheduled__2024-05-16T21:04:00+00:00 [running]> on host c2067b412cfb
[2024-05-16T21:06:11.704+0000] {taskinstance.py:2648} INFO - Exporting env vars: AIRFLOW_CTX_DAG_OWNER='***' AIRFLOW_CTX_DAG_ID='data_ingestion' AIRFLOW_CTX_TASK_ID='read_data' AIRFLOW_CTX_EXECUTION_DATE='2024-05-16T21:04:00+00:00' AIRFLOW_CTX_TRY_NUMBER='2' AIRFLOW_CTX_DAG_RUN_ID='scheduled__2024-05-16T21:04:00+00:00'
[2024-05-16T21:06:11.705+0000] {taskinstance.py:430} INFO - ::endgroup::
[2024-05-16T21:06:11.719+0000] {taskinstance.py:441} INFO - ::group::Post task execution logs
[2024-05-16T21:06:11.720+0000] {taskinstance.py:2905} ERROR - Task failed with exception
Traceback (most recent call last):
  File "/home/airflow/.local/lib/python3.12/site-packages/airflow/models/taskinstance.py", line 465, in _execute_task
    result = _execute_callable(context=context, **execute_callable_kwargs)
             ^^^^^^^^^^^^^^^^^^^^^^^^^^^^^^^^^^^^^^^^^^^^^^^^^^^^^^^^^^^^^
  File "/home/airflow/.local/lib/python3.12/site-packages/airflow/models/taskinstance.py", line 432, in _execute_callable
    return execute_callable(context=context, **execute_callable_kwargs)
           ^^^^^^^^^^^^^^^^^^^^^^^^^^^^^^^^^^^^^^^^^^^^^^^^^^^^^^^^^^^^
  File "/home/airflow/.local/lib/python3.12/site-packages/airflow/models/baseoperator.py", line 400, in wrapper
    return func(self, *args, **kwargs)
           ^^^^^^^^^^^^^^^^^^^^^^^^^^^
  File "/home/airflow/.local/lib/python3.12/site-packages/airflow/operators/python.py", line 235, in execute
    return_value = self.execute_callable()
                   ^^^^^^^^^^^^^^^^^^^^^^^
  File "/home/airflow/.local/lib/python3.12/site-packages/airflow/operators/python.py", line 252, in execute_callable
    return self.python_callable(*self.op_args, **self.op_kwargs)
           ^^^^^^^^^^^^^^^^^^^^^^^^^^^^^^^^^^^^^^^^^^^^^^^^^^^^^
  File "/opt/airflow/dags/first_dag.py", line 25, in read_data
    files = os.listdir(raw_data_path)
            ^^^^^^^^^^^^^^^^^^^^^^^^^
FileNotFoundError: [Errno 2] No such file or directory: 'C:\\Users\\salma elyagoubi\\error418\\raw-data'
[2024-05-16T21:06:11.734+0000] {taskinstance.py:1206} INFO - Marking task as FAILED. dag_id=data_ingestion, task_id=read_data, run_id=scheduled__2024-05-16T21:04:00+00:00, execution_date=20240516T210400, start_date=20240516T210611, end_date=20240516T210611
[2024-05-16T21:06:11.748+0000] {standard_task_runner.py:110} ERROR - Failed to execute job 16 for task read_data ([Errno 2] No such file or directory: 'C:\\Users\\salma elyagoubi\\error418\\raw-data'; 574)
[2024-05-16T21:06:11.777+0000] {local_task_job_runner.py:240} INFO - Task exited with return code 1
[2024-05-16T21:06:11.814+0000] {taskinstance.py:3498} INFO - 0 downstream tasks scheduled from follow-on schedule check
[2024-05-16T21:06:11.822+0000] {local_task_job_runner.py:222} INFO - ::endgroup::
