[2024-05-16T21:03:06.955+0000] {local_task_job_runner.py:120} INFO - ::group::Pre task execution logs
[2024-05-16T21:03:06.997+0000] {taskinstance.py:2076} INFO - Dependencies all met for dep_context=non-requeueable deps ti=<TaskInstance: data_ingestion.read_data scheduled__2024-05-16T21:02:00+00:00 [queued]>
[2024-05-16T21:03:07.008+0000] {taskinstance.py:2076} INFO - Dependencies all met for dep_context=requeueable deps ti=<TaskInstance: data_ingestion.read_data scheduled__2024-05-16T21:02:00+00:00 [queued]>
[2024-05-16T21:03:07.011+0000] {taskinstance.py:2306} INFO - Starting attempt 1 of 2
[2024-05-16T21:03:07.032+0000] {taskinstance.py:2330} INFO - Executing <Task(PythonOperator): read_data> on 2024-05-16 21:02:00+00:00
[2024-05-16T21:03:07.041+0000] {warnings.py:110} WARNING - /home/***/.local/lib/python3.12/site-packages/***/task/task_runner/standard_task_runner.py:61: DeprecationWarning: This process (pid=319) is multi-threaded, use of fork() may lead to deadlocks in the child.
  pid = os.fork()

[2024-05-16T21:03:07.044+0000] {standard_task_runner.py:63} INFO - Started process 338 to run task
[2024-05-16T21:03:07.044+0000] {standard_task_runner.py:90} INFO - Running: ['***', 'tasks', 'run', 'data_ingestion', 'read_data', 'scheduled__2024-05-16T21:02:00+00:00', '--job-id', '6', '--raw', '--subdir', 'DAGS_FOLDER/first_dag.py', '--cfg-path', '/tmp/tmp6g5grs8d']
[2024-05-16T21:03:07.046+0000] {standard_task_runner.py:91} INFO - Job 6: Subtask read_data
[2024-05-16T21:03:07.116+0000] {task_command.py:426} INFO - Running <TaskInstance: data_ingestion.read_data scheduled__2024-05-16T21:02:00+00:00 [running]> on host c2067b412cfb
[2024-05-16T21:03:07.220+0000] {taskinstance.py:2648} INFO - Exporting env vars: AIRFLOW_CTX_DAG_OWNER='***' AIRFLOW_CTX_DAG_ID='data_ingestion' AIRFLOW_CTX_TASK_ID='read_data' AIRFLOW_CTX_EXECUTION_DATE='2024-05-16T21:02:00+00:00' AIRFLOW_CTX_TRY_NUMBER='1' AIRFLOW_CTX_DAG_RUN_ID='scheduled__2024-05-16T21:02:00+00:00'
[2024-05-16T21:03:07.222+0000] {taskinstance.py:430} INFO - ::endgroup::
[2024-05-16T21:03:07.239+0000] {taskinstance.py:441} INFO - ::group::Post task execution logs
[2024-05-16T21:03:07.240+0000] {taskinstance.py:2905} ERROR - Task failed with exception
Traceback (most recent call last):
  File "/home/airflow/.local/lib/python3.12/site-packages/airflow/models/taskinstance.py", line 465, in _execute_task
    result = _execute_callable(context=context, **execute_callable_kwargs)
             ^^^^^^^^^^^^^^^^^^^^^^^^^^^^^^^^^^^^^^^^^^^^^^^^^^^^^^^^^^^^^
  File "/home/airflow/.local/lib/python3.12/site-packages/airflow/models/taskinstance.py", line 432, in _execute_callable
    return execute_callable(context=context, **execute_callable_kwargs)
           ^^^^^^^^^^^^^^^^^^^^^^^^^^^^^^^^^^^^^^^^^^^^^^^^^^^^^^^^^^^^
  File "/home/airflow/.local/lib/python3.12/site-packages/airflow/models/baseoperator.py", line 400, in wrapper
    return func(self, *args, **kwargs)
           ^^^^^^^^^^^^^^^^^^^^^^^^^^^
  File "/home/airflow/.local/lib/python3.12/site-packages/airflow/operators/python.py", line 235, in execute
    return_value = self.execute_callable()
                   ^^^^^^^^^^^^^^^^^^^^^^^
  File "/home/airflow/.local/lib/python3.12/site-packages/airflow/operators/python.py", line 252, in execute_callable
    return self.python_callable(*self.op_args, **self.op_kwargs)
           ^^^^^^^^^^^^^^^^^^^^^^^^^^^^^^^^^^^^^^^^^^^^^^^^^^^^^
  File "/opt/airflow/dags/first_dag.py", line 25, in read_data
    files = os.listdir(raw_data_path)
            ^^^^^^^^^^^^^^^^^^^^^^^^^
FileNotFoundError: [Errno 2] No such file or directory: 'C:/Users/salma elyagoubi/error418/raw-data'
[2024-05-16T21:03:07.253+0000] {taskinstance.py:1206} INFO - Marking task as UP_FOR_RETRY. dag_id=data_ingestion, task_id=read_data, run_id=scheduled__2024-05-16T21:02:00+00:00, execution_date=20240516T210200, start_date=20240516T210306, end_date=20240516T210307
[2024-05-16T21:03:07.267+0000] {standard_task_runner.py:110} ERROR - Failed to execute job 6 for task read_data ([Errno 2] No such file or directory: 'C:/Users/salma elyagoubi/error418/raw-data'; 338)
[2024-05-16T21:03:07.299+0000] {local_task_job_runner.py:240} INFO - Task exited with return code 1
[2024-05-16T21:03:07.329+0000] {taskinstance.py:3498} INFO - 0 downstream tasks scheduled from follow-on schedule check
[2024-05-16T21:03:07.332+0000] {local_task_job_runner.py:222} INFO - ::endgroup::
