[2024-05-16T20:35:33.100+0000] {task_context_logger.py:104} ERROR - Executor reports task instance <TaskInstance: data_ingestion.read_data scheduled__2024-05-16T20:34:00+00:00 [queued]> finished (failed) although the task says it's queued. (Info: None) Was the task killed externally?
