[2024-05-17T20:17:36.724+0000] {local_task_job_runner.py:120} INFO - ::group::Pre task execution logs
[2024-05-17T20:17:36.797+0000] {taskinstance.py:2076} INFO - Dependencies all met for dep_context=non-requeueable deps ti=<TaskInstance: data_ingestion_pipelines_2.save_data_errors manual__2024-05-17T12:31:17.083416+00:00 [queued]>
[2024-05-17T20:17:36.816+0000] {taskinstance.py:2076} INFO - Dependencies all met for dep_context=requeueable deps ti=<TaskInstance: data_ingestion_pipelines_2.save_data_errors manual__2024-05-17T12:31:17.083416+00:00 [queued]>
[2024-05-17T20:17:36.817+0000] {taskinstance.py:2306} INFO - Starting attempt 3 of 3
[2024-05-17T20:17:36.845+0000] {taskinstance.py:2330} INFO - Executing <Task(PythonOperator): save_data_errors> on 2024-05-17 12:31:17.083416+00:00
[2024-05-17T20:17:36.864+0000] {warnings.py:110} WARNING - /home/***/.local/lib/python3.12/site-packages/***/task/task_runner/standard_task_runner.py:61: DeprecationWarning: This process (pid=8687) is multi-threaded, use of fork() may lead to deadlocks in the child.
  pid = os.fork()

[2024-05-17T20:17:36.867+0000] {standard_task_runner.py:63} INFO - Started process 8714 to run task
[2024-05-17T20:17:36.867+0000] {standard_task_runner.py:90} INFO - Running: ['***', 'tasks', 'run', 'data_ingestion_pipelines_2', 'save_data_errors', 'manual__2024-05-17T12:31:17.083416+00:00', '--job-id', '59', '--raw', '--subdir', 'DAGS_FOLDER/data-ingestion-dag.py', '--cfg-path', '/tmp/tmpa8crskak']
[2024-05-17T20:17:36.869+0000] {standard_task_runner.py:91} INFO - Job 59: Subtask save_data_errors
[2024-05-17T20:17:36.973+0000] {task_command.py:426} INFO - Running <TaskInstance: data_ingestion_pipelines_2.save_data_errors manual__2024-05-17T12:31:17.083416+00:00 [running]> on host e512d0910ba5
[2024-05-17T20:17:37.170+0000] {taskinstance.py:2648} INFO - Exporting env vars: AIRFLOW_CTX_DAG_OWNER='***' AIRFLOW_CTX_DAG_ID='data_ingestion_pipelines_2' AIRFLOW_CTX_TASK_ID='save_data_errors' AIRFLOW_CTX_EXECUTION_DATE='2024-05-17T12:31:17.083416+00:00' AIRFLOW_CTX_TRY_NUMBER='3' AIRFLOW_CTX_DAG_RUN_ID='manual__2024-05-17T12:31:17.083416+00:00'
[2024-05-17T20:17:37.176+0000] {taskinstance.py:430} INFO - ::endgroup::
[2024-05-17T20:17:37.212+0000] {warnings.py:110} WARNING - /opt/***/dags/data-ingestion-dag.py:287: DeprecationWarning: There is no current event loop
  loop = asyncio.get_event_loop()

[2024-05-17T20:17:37.233+0000] {taskinstance.py:441} INFO - ::group::Post task execution logs
[2024-05-17T20:17:37.234+0000] {taskinstance.py:2905} ERROR - Task failed with exception
Traceback (most recent call last):
  File "/home/airflow/.local/lib/python3.12/site-packages/airflow/models/taskinstance.py", line 465, in _execute_task
    result = _execute_callable(context=context, **execute_callable_kwargs)
             ^^^^^^^^^^^^^^^^^^^^^^^^^^^^^^^^^^^^^^^^^^^^^^^^^^^^^^^^^^^^^
  File "/home/airflow/.local/lib/python3.12/site-packages/airflow/models/taskinstance.py", line 432, in _execute_callable
    return execute_callable(context=context, **execute_callable_kwargs)
           ^^^^^^^^^^^^^^^^^^^^^^^^^^^^^^^^^^^^^^^^^^^^^^^^^^^^^^^^^^^^
  File "/home/airflow/.local/lib/python3.12/site-packages/airflow/models/baseoperator.py", line 400, in wrapper
    return func(self, *args, **kwargs)
           ^^^^^^^^^^^^^^^^^^^^^^^^^^^
  File "/home/airflow/.local/lib/python3.12/site-packages/airflow/operators/python.py", line 235, in execute
    return_value = self.execute_callable()
                   ^^^^^^^^^^^^^^^^^^^^^^^
  File "/home/airflow/.local/lib/python3.12/site-packages/airflow/operators/python.py", line 252, in execute_callable
    return self.python_callable(*self.op_args, **self.op_kwargs)
           ^^^^^^^^^^^^^^^^^^^^^^^^^^^^^^^^^^^^^^^^^^^^^^^^^^^^^
  File "/opt/airflow/dags/data-ingestion-dag.py", line 288, in save_data_errors
    loop.run_until_complete(save_data_errors_async(kwargs['ti']))
  File "/usr/local/lib/python3.12/asyncio/base_events.py", line 687, in run_until_complete
    return future.result()
           ^^^^^^^^^^^^^^^
  File "/opt/airflow/dags/data-ingestion-dag.py", line 216, in save_data_errors_async
    conn = await create_db_connection()
           ^^^^^^^^^^^^^^^^^^^^^^^^^^^^
  File "/opt/airflow/dags/data-ingestion-dag.py", line 26, in create_db_connection
    return await asyncpg.connect(
           ^^^^^^^^^^^^^^^^^^^^^^
  File "/home/airflow/.local/lib/python3.12/site-packages/asyncpg/connection.py", line 2329, in connect
    return await connect_utils._connect(
           ^^^^^^^^^^^^^^^^^^^^^^^^^^^^^
  File "/home/airflow/.local/lib/python3.12/site-packages/asyncpg/connect_utils.py", line 1017, in _connect
    raise last_error or exceptions.TargetServerAttributeNotMatched(
  File "/home/airflow/.local/lib/python3.12/site-packages/asyncpg/connect_utils.py", line 991, in _connect
    conn = await _connect_addr(
           ^^^^^^^^^^^^^^^^^^^^
  File "/home/airflow/.local/lib/python3.12/site-packages/asyncpg/connect_utils.py", line 828, in _connect_addr
    return await __connect_addr(params, True, *args)
           ^^^^^^^^^^^^^^^^^^^^^^^^^^^^^^^^^^^^^^^^^
  File "/home/airflow/.local/lib/python3.12/site-packages/asyncpg/connect_utils.py", line 873, in __connect_addr
    tr, pr = await connector
             ^^^^^^^^^^^^^^^
  File "/home/airflow/.local/lib/python3.12/site-packages/asyncpg/connect_utils.py", line 744, in _create_ssl_connection
    tr, pr = await loop.create_connection(
             ^^^^^^^^^^^^^^^^^^^^^^^^^^^^^
  File "/usr/local/lib/python3.12/asyncio/base_events.py", line 1130, in create_connection
    raise OSError('Multiple exceptions: {}'.format(
OSError: Multiple exceptions: [Errno 111] Connect call failed ('127.0.0.1', 5432), [Errno 99] Cannot assign requested address
[2024-05-17T20:17:37.262+0000] {taskinstance.py:1206} INFO - Marking task as FAILED. dag_id=data_ingestion_pipelines_2, task_id=save_data_errors, run_id=manual__2024-05-17T12:31:17.083416+00:00, execution_date=20240517T123117, start_date=20240517T201736, end_date=20240517T201737
[2024-05-17T20:17:37.283+0000] {standard_task_runner.py:110} ERROR - Failed to execute job 59 for task save_data_errors (Multiple exceptions: [Errno 111] Connect call failed ('127.0.0.1', 5432), [Errno 99] Cannot assign requested address; 8714)
[2024-05-17T20:17:37.324+0000] {local_task_job_runner.py:240} INFO - Task exited with return code 1
[2024-05-17T20:17:37.368+0000] {taskinstance.py:3498} INFO - 0 downstream tasks scheduled from follow-on schedule check
[2024-05-17T20:17:37.373+0000] {local_task_job_runner.py:222} INFO - ::endgroup::
